<?xml version="1.0" ?>
<!-- This URDF was automatically created by SolidWorks to URDF Exporter! Originally created by Stephen Brawner (brawner@gmail.com) 
     Commit Version: 1.6.0-4-g7f85cfe  Build Version: 1.6.7995.38578
     For more information, please see http://wiki.ros.org/sw_urdf_exporter -->
<robot
  name="ur10" xmlns:xacro="http://ros.org/wiki/xacro">

  <link name="world"/>
      <joint name="base_link_joint" type="fixed">
          <origin xyz="0 0 0" rpy="0 0 0"/>
          <parent link="world"/>
          <child link="base_link"/>
      </joint>

  <link
    name="base_link">
    <inertial>
      <origin
        xyz="6.99094974730696E-06 -0.000159353517555083 0.0184354407542913"
        rpy="0 0 0" />
      <mass
        value="0.706324323688928" />
      <inertia
        ixx="0.00115557612091012"
        ixy="4.80089164310127E-08"
        ixz="7.8755061911207E-08"
        iyy="0.00114584541323477"
        iyz="1.99545213436521E-07"
        izz="0.00212897019994227" />
    </inertial>
    <visual>
      <origin
        xyz="0 0 0"
        rpy="0 0 0" />
      <geometry>
        <mesh
          filename="package://ur10/meshes/base_link.STL" />
      </geometry>
      <material
        name="">
        <color
          rgba="0.792156862745098 0.819607843137255 0.933333333333333 1" />
      </material>
    </visual>
    <collision>
      <origin
        xyz="0 0 0"
        rpy="0 0 0" />
      <geometry>
        <mesh
          filename="package://ur10/meshes/base_link.STL" />
      </geometry>
    </collision>
  </link>
  <link
    name="link1">
    <inertial>
      <origin
        xyz="4.71773526128372E-06 0.0120536615771912 0.0784763122055467"
        rpy="0 0 0" />
      <mass
        value="3.07355036547625" />
      <inertia
        ixx="0.0114771434116216"
        ixy="-2.06679278249525E-07"
        ixz="-9.91030270639159E-07"
        iyy="0.0107166357827127"
        iyz="-0.000858549847549967"
        izz="0.0101197474335884" />
    </inertial>
    <visual>
      <origin
        xyz="0 0 0"
        rpy="0 0 0" />
      <geometry>
        <mesh
          filename="package://ur10/meshes/link1.STL" />
      </geometry>
      <material
        name="">
        <color
          rgba="0.792156862745098 0.819607843137255 0.933333333333333 1" />
      </material>
    </visual>
    <collision>
      <origin
        xyz="0 0 0"
        rpy="0 0 0" />
      <geometry>
        <mesh
          filename="package://ur10/meshes/link1.STL" />
      </geometry>
    </collision>
  </link>
  <joint
    name="joint1"
    type="revolute">
    <origin
      xyz="0 -0.00043847 0.038"
      rpy="0 0 0" />
    <parent
      link="base_link" />
    <child
      link="link1" />
    <axis
      xyz="0 0 1" />
    <limit
      lower="-50"
      upper="50"
      effort="0"
      velocity="0" />
  </joint>
  <link
    name="link2">
    <inertial>
      <origin
        xyz="-8.33371701090824E-06 -0.251045155802553 0.084336759623579"
        rpy="0 0 0" />
      <mass
        value="8.71240997645227" />
      <inertia
        ixx="0.0965259604237775"
        ixy="-5.65864767608362E-09"
        ixz="3.68281322600701E-06"
        iyy="0.0199170991926185"
        iyz="0.000589153449770856"
        izz="0.0949166238737584" />
    </inertial>
    <visual>
      <origin
        xyz="0 0 0"
        rpy="0 0 0" />
      <geometry>
        <mesh
          filename="package://ur10/meshes/link2.STL" />
      </geometry>
      <material
        name="">
        <color
          rgba="0.792156862745098 0.819607843137255 0.933333333333333 1" />
      </material>
    </visual>
    <collision>
      <origin
        xyz="0 0 0"
        rpy="0 0 0" />
      <geometry>
        <mesh
          filename="package://ur10/meshes/link2.STL" />
      </geometry>
    </collision>
  </link>
  <joint
    name="joint2"
    type="revolute">
    <origin
      xyz="0 0.086438 0.09"
      rpy="-1.5708 0 0" />
    <parent
      link="link1" />
    <child
      link="link2" />
    <axis
      xyz="0 0 1" />
    <limit
      lower="-50"
      upper="50"
      effort="0"
      velocity="0" />
  </joint>
  <link
    name="link3">
    <inertial>
      <origin
        xyz="0.256921622587735 -0.00114919188339613 0.05646938880001"
        rpy="0 0 0" />
      <mass
        value="4.65343475090671" />
      <inertia
        ixx="0.00595615847264998"
        ixy="0.000204077851163617"
        ixz="-0.000130408961366202"
        iyy="0.0517117713534692"
        iyz="1.56550769818929E-07"
        izz="0.0514235400102428" />
    </inertial>
    <visual>
      <origin
        xyz="0 0 0"
        rpy="0 0 0" />
      <geometry>
        <mesh
          filename="package://ur10/meshes/link3.STL" />
      </geometry>
      <material
        name="">
        <color
          rgba="0.792156862745098 0.819607843137255 0.933333333333333 1" />
      </material>
    </visual>
    <collision>
      <origin
        xyz="0 0 0"
        rpy="0 0 0" />
      <geometry>
        <mesh
          filename="package://ur10/meshes/link3.STL" />
      </geometry>
    </collision>
  </link>
  <joint
    name="joint3"
    type="revolute">
    <origin
      xyz="0 -0.6129 0.021891"
      rpy="-3.1416 0 -1.5708" />
    <parent
      link="link2" />
    <child
      link="link3" />
    <axis
      xyz="0 0 1" />
    <limit
      lower="-50"
      upper="50"
      effort="0"
      velocity="0" />
  </joint>
  <link
    name="link4">
    <inertial>
      <origin
        xyz="0.00973735157071443 2.67860039353252E-06 0.0463972280659702"
        rpy="0 0 0" />
      <mass
        value="0.728503733480583" />
      <inertia
        ixx="0.000883756617840841"
        ixy="7.58522256251456E-08"
        ixz="-9.07970442506574E-05"
        iyy="0.00111504666078434"
        iyz="3.05789109797123E-08"
        izz="0.00103094357618064" />
    </inertial>
    <visual>
      <origin
        xyz="0 0 0"
        rpy="0 0 0" />
      <geometry>
        <mesh
          filename="package://ur10/meshes/link4.STL" />
      </geometry>
      <material
        name="">
        <color
          rgba="0.792156862745098 0.819607843137255 0.933333333333333 1" />
      </material>
    </visual>
    <collision>
      <origin
        xyz="0 0 0"
        rpy="0 0 0" />
      <geometry>
        <mesh
          filename="package://ur10/meshes/link4.STL" />
      </geometry>
    </collision>
  </link>
  <joint
    name="joint4"
    type="revolute">
    <origin
      xyz="0.57159 -0.0025605 -0.002"
      rpy="-3.1416 0 0" />
    <parent
      link="link3" />
    <child
      link="link4" />
    <axis
      xyz="0 0 1" />
    <limit
      lower="-50"
      upper="50"
      effort="0"
      velocity="0" />
  </joint>
  <link
    name="link5">
    <inertial>
      <origin
        xyz="-3.54827412121783E-06 0.00973751267937696 0.0463971682147017"
        rpy="0 0 0" />
      <mass
        value="0.728508494010888" />
      <inertia
        ixx="0.0011150507496292"
        ixy="-7.87059566917945E-08"
        ixz="-2.89888899452125E-08"
        iyy="0.000883745086730893"
        iyz="-9.07966561134036E-05"
        izz="0.00103092076650608" />
    </inertial>
    <visual>
      <origin
        xyz="0 0 0"
        rpy="0 0 0" />
      <geometry>
        <mesh
          filename="package://ur10/meshes/link5.STL" />
      </geometry>
      <material
        name="">
        <color
          rgba="0.792156862745098 0.819607843137255 0.933333333333333 1" />
      </material>
    </visual>
    <collision>
      <origin
        xyz="0 0 0"
        rpy="0 0 0" />
      <geometry>
        <mesh
          filename="package://ur10/meshes/link5.STL" />
      </geometry>
    </collision>
  </link>
  <joint
    name="joint5"
    type="revolute">
    <origin
      xyz="0.0617 0 0.054"
      rpy="1.5708 0 1.5708" />
    <parent
      link="link4" />
    <child
      link="link5" />
    <axis
      xyz="0 0 1" />
    <limit
      lower="-50"
      upper="50"
      effort="0"
      velocity="0" />
  </joint>
  <link
    name="link6">
    <inertial>
      <origin
        xyz="-1.7505722804359E-05 0.000603631690059281 -0.042393391727179"
        rpy="0 0 0" />
      <mass
        value="0.251003443936112" />
      <inertia
        ixx="0.000114086534671522"
        ixy="2.97539535553898E-06"
        ixz="1.70309941223874E-08"
        iyy="0.000117618235951477"
        iyz="-4.78246250199236E-07"
        izz="0.000197153479224867" />
    </inertial>
    <visual>
      <origin
        xyz="0 0 0"
        rpy="0 0 0" />
      <geometry>
        <mesh
          filename="package://ur10/meshes/link6.STL" />
      </geometry>
      <material
        name="">
        <color
          rgba="0.792156862745098 0.819607843137255 0.933333333333333 1" />
      </material>
    </visual>
    <collision>
      <origin
        xyz="0 0 0"
        rpy="0 0 0" />
      <geometry>
        <mesh
          filename="package://ur10/meshes/link6.STL" />
      </geometry>
    </collision>
  </link>
  <joint
    name="joint6"
    type="revolute">
    <origin
      xyz="0 0.1292 0.054"
      rpy="-1.5708 0 0" />
    <parent
      link="link5" />
    <child
      link="link6" />
    <axis
      xyz="0 0 1" />
    <limit
      lower="-50"
      upper="50"
      effort="0"
      velocity="0" />
  </joint>

   <!-- ##### Joint Controlllers #####-->

    <ros2_control name="GazeboSystem" type="system">
    <hardware>
      <plugin>gazebo_ros2_control/GazeboSystem</plugin>
      </hardware>

      <!-- Joint 1 position controller-->
      <joint name="joint1">
        <command_interface name="position">
          <param name="min">-6.2832</param>
          <param name="max">6.2832</param>
        </command_interface>
        <state_interface name="position"/>
        <state_interface name="velocity"/>
      </joint>

      <!-- Joint 1 velocity controller-->
      <joint name="joint1">
        <command_interface name="velocity">
          <param name="min">-1000</param>
          <param name="max">1000</param>
        </command_interface>
        <state_interface name="position"/>
        <state_interface name="velocity"/>
      </joint>

      <!-- Joint 2 controller-->
      <joint name="joint2">
        <command_interface name="position">
          <param name="min">-6.2832</param>
          <param name="max">6.2832</param>
        </command_interface>
        <state_interface name="position"/>
        <state_interface name="velocity"/>
      </joint>

      <!-- Joint 2 velocity controller-->
      <joint name="joint2">
        <command_interface name="velocity">
          <param name="min">-1000</param>
          <param name="max">1000</param>
        </command_interface>
        <state_interface name="position"/>
        <state_interface name="velocity"/>
      </joint>

      <!-- Joint 3 position controller-->
      <joint name="joint3">
        <command_interface name="position">
          <param name="min">-2.7925</param>
          <param name="max">2.7925</param>
        </command_interface>
        <state_interface name="position"/>
        <state_interface name="velocity"/>
      </joint>

      <!-- Joint 3 velocity controller-->
      <joint name="joint3">
        <command_interface name="velocity">
          <param name="min">-1000</param>
          <param name="max">1000</param>
        </command_interface>
        <state_interface name="position"/>
        <state_interface name="velocity"/>
      </joint>

      <!-- Joint 4 position controller-->
      <joint name="joint4">
        <command_interface name="position">
          <param name="min">-6.2832</param>
          <param name="max">6.2832</param>
        </command_interface>
        <state_interface name="position"/>
        <state_interface name="velocity"/>
      </joint>

      <!-- Joint 4 velocity controller-->
      <joint name="joint4">
        <command_interface name="velocity">
          <param name="min">-1000</param>
          <param name="max">1000</param>
        </command_interface>
        <state_interface name="position"/>
        <state_interface name="velocity"/>
      </joint>

      <!-- Joint 5 position controller-->
      <joint name="joint5">
        <command_interface name="position">
          <param name="min">-6.2832</param>
          <param name="max">6.2832</param>
        </command_interface>
        <state_interface name="position"/>
        <state_interface name="velocity"/>
      </joint>

      <!-- Joint 5 velocity controller-->
      <joint name="joint1">
        <command_interface name="velocity">
          <param name="min">-1000</param>
          <param name="max">1000</param>
        </command_interface>
        <state_interface name="position"/>
        <state_interface name="velocity"/>
      </joint>

      <!-- Joint 6 position controller-->
      <joint name="joint6">
        <command_interface name="position">
          <param name="min">-6.2832</param>
          <param name="max">6.2832</param>
        </command_interface>
        <state_interface name="position"/>
        <state_interface name="velocity"/>
      </joint>

      <!-- Joint 6 velocity controller-->
      <joint name="joint6">
        <command_interface name="velocity">
          <param name="min">-1000</param>
          <param name="max">1000</param>
        </command_interface>
        <state_interface name="position"/>
        <state_interface name="velocity"/>
      </joint>

    </ros2_control>

  <gazebo>
    <plugin name="gazebo_ros2_control" filename="libgazebo_ros2_control.so">
      <robot_sim_type>gazebo_ros2_control/GazeboSystem</robot_sim_type>
      <parameters>$(find ur10)/config/control.yaml</parameters>
      </plugin>
  </gazebo>

  <gazebo>
  <plugin name='vacuum_gripper' filename='libgazebo_ros_vacuum_gripper.so'>

    <!-- This part can be commented out if not required -->
    <ros>

      <!-- Add a namespace -->

      <namespace>/demo</namespace>

      <!-- Remapping service and topic names -->
      <remapping>switch:=custom_switch</remapping>
      <remapping>grasping:=custom_grasping</remapping>
    </ros>

    <!-- Link associated with gripper -->
    <link_name>link6</link_name>

    <!-- Max distance to attract entities -->
    <max_distance>0.3</max_distance>

    <!-- List of entities to be not attracted by the gripper -->
    <fixed>ground_plane</fixed>
    <fixed>wall</fixed>

  </plugin>
</gazebo>

</robot>